try
{
    miFuncion();
}
catch (e)
{
    console.log("Ocurri√≥ un error, es el siguiente: " + e);
}